Workbook
Name AttributeType: #REF!
Name AttributeType2: #REF!
Name BooleanValues: #REF!
Name brand: [1]lookup!$A$2:$A$25
Name CBD_SHOE_HEIGHT: [2]drop_down!$B$2:$B$5
Name ColorControlMode: #REF!
Name ComponentComposition: #REF!
Name CompositesConstruction: #REF!
Name coo: [1]lookup!$D$2:$D$25
Name CorrugatedMaterial: #REF!
Name CurrencyCode: #REF!
Name DisplayMode: #REF!
Name ElasticStructure: #REF!
Name EndType: #REF!
Name FoldType: #REF!
Name group: [1]lookup!$B$2:$B$25
Name HookEyeBarApp: #REF!
Name HookLoopApp: #REF!
Name HookLoopForm: #REF!
Name InternalExternal: #REF!
Name kl: #REF!
Name KnitType: #REF!
Name LabelApp: #REF!
Name LabelLanguage: #REF!
Name LeatherSatra: #REF!
Name LeatherSubtype: #REF!
Name LeatherThickness: #REF!
Name LeatherType: #REF!
Name Level: #REF!
Name lo: [1]lookup!$C$2:$C$25
Name MaterialComposition: #REF!
Name MaterialDevelopmentStatus: #REF!
Name MaterialPricingMode: #REF!
Name MaterialSupplierStatus: #REF!
Name MetalCategory: #REF!
Name MetalForm: #REF!
Name MetalShape: #REF!
Name PackagingCoatingFinishing: #REF!
Name PackagingMaterialQuality: #REF!
Name PackagingType: #REF!
Name PaymentTerms: #REF!
Name ProductSampleType: #REF!
Name RawMaterial: #REF!
Name SampleProductType: #REF!
Name SampleStatus: #REF!
Name SampleSubType: #REF!
Name SampleType: #REF!
Name Scope: #REF!
Name Shipping: #REF!
Name SizeWeight: #REF!
Name SnapCover: #REF!
Name source: [3]TechPack!$M$2:$M$11
Name SpecialClaims: #REF!
Name StampFinishPattern: #REF!
Name Standard: #REF!
Name Strength: #REF!
Name Structure: #REF!
Name SubA: [4]Materials!$M$30
Name SubB: [4]Materials!$M$36
Name SubC: [4]Materials!$M$40

Sheet Footwear-Detailed-Breakdown
M1: 6
C2: Footwear Cost Break Down
C5: PRODUCT SUMMARY
C6: SEASON: | D6: {*du|var:plmSeasonName|locked} | F6: PLM PRODUCT #: | G6: {*du|var:plmProductNumber|locked} | I6: COLORWAY NAME: | J6: {*d|var:costSheetSelectedColorwayNames|locked} | N6: USER EMAIL: | O6: {*ud|var:exportedUserMail}
C7: COST SHEET MILESTONE: | F7: PRODUCT DESCRIPTION: | G7: {*d|var:scProductDescription|locked|ft:com.lcs.wc.product.LCSProduct} | I7: COLORWAY #: | J7: {*du|var:costSheetSelectedColorwayIds|locked} | N7: REP COLORWAY FORECAST: | O7: {*d|var:scInitialEstimatedUnits|locked|ft:com.lcs.wc.season.LCSSKUSeasonLink}
C8: COST SHEET NAME: | D8: {*du|var:name} | F8: GENDER: | G8: {*d|var:scGender|locked|ft:com.lcs.wc.product.LCSProduct} | I8: REPRESENTATIVE COLORWAY: | J8: {*d|var:representativeColorwayName|locked} | N8: TARGET VENDOR QUOTE: | O8: {*d|var:scTargetVendorQuote|locked|ft:com.lcs.wc.sourcing.LCSCostSheet}
C9: COST SHEET NUMBER: | D9: {*du|var:scCostSheetNumber|locked} | F9: AGE GROUP: | G9: {*d|var:scAge|locked|ft:com.lcs.wc.product.LCSProduct} | I9: SIZE RANGE: | J9: {*d|var:scSizeRange|locked|ft:com.lcs.wc.product.LCSProduct}
C10: SOURCING CONFIG: | D10: {*d|var:sourcingConfigName|locked} | F10: DEVELOPMENT TYPE: | G10: {*d|var:scdevelopmentype|locked|ft:com.lcs.wc.season.LCSSeasonProductLink} | I10: COSTING SIZE: | J10: {*ud|var:scCostingSize|ft:com.lcs.wc.sourcing.LCSCostSheet}
C11: COUNTRY OF ORIGIN | D11: {*d|var:countryOfOrigin|locked} | F11: OUTSOLE: | G11: {*d|var:scOutsole|locked|ft:com.lcs.wc.product.LCSProduct} | I11: SAMPLE SIZE:
C12: SPECIFICATION: | D12: {*d|var:specificationName|locked} | F12: LAST: | G12: {*d|var:scLast|locked|ft:com.lcs.wc.product.LCSProduct}
C15: COST SUMMARY
D17: COST INPUTS | G17: FOB BREAKDOWN | K17: LABOR & OVERHEAD
D19: Vendor Cost Sheet Status | G19: Total Materials | H19: =IF(H26>0,H26,(SUM(H20:H25))) -> 0 | K19: UPPER PREPARATION | M19: Flex Attribtue Name (hide on doc) | N19: TCT (mins) | O19: STOCKFITTING | Q19: Flex Attribtue Name (hide on doc) | R19: TCT (mins) | V19: Additional Override Attributes
D20: Incoterms | G20: Total Upper | H20: =SUMIF(C51:C201,'Data Validation'!A2,S51:S201)+SUMIF(C206:C220,'Data Validation'!A2,S206:S211) -> 0 | I20: BOM + Additional BOM | K20: # Textile/ synthetic pcs. | L20: =W49 -> 0 | M20: # Textile/ synthetic pcs. TCT (mins) | N20: =VLOOKUP(CONCATENATE("# Cut & Prep NON-LEATHER",L20),'TCT Lookup'!A:E,5,FALSE) -> 0 | O20: # Bottom pieces | P20: =AF49 -> 0 | Q20: # Bottom pieces TCT (mins) | R20: =IFERROR(VLOOKUP(CONCATENATE("# Bottom pieces",P20),'TCT Lookup'!A:E,5,FALSE),0) -> 0 | V20: =SUMIF(C206:C220,'Data Validation'!A2,S206:S211) -> 0
D21: Incoterms Location | G21: Total Sockliner | H21: =SUMIF(C51:C201,'Data Validation'!A3,S51:S201)+SUMIF(C206:C220,'Data Validation'!A3,S206:S211) -> 0 | I21: BOM + Additional BOM | K21: # Textile/ synthetic pcs for single layer cutting | L21: =X49 -> 0 | M21: # Textile/ synthetic pcs for single layer cutting TCT (mins) | N21: =VLOOKUP(CONCATENATE("# Cut & Prep Non-leather pieces for single layer cutting",L21),'TCT Lookup'!A:E,5,FALSE) -> 0 | O21: # Recess points and # Emboss/deboss windows | P21: 1 | Q21: # Recess points and # Emboss/deboss windows TCT (mins) | R21: =IFERROR(VLOOKUP(CONCATENATE("# Recess points and # Emboss/deboss windows",P21),'TCT Lookup'!A:E,5,FALSE),0) -> 0.2141914 | V21: =SUMIF(C206:C220,'Data Validation'!A3,S206:S211) -> 0
D22: Quote Good From | E22: {*du|var:scQuoteGoodFrom|ft:com.lcs.wc.sourcing.LCSCostSheet|param:DATE_FORMAT~mm/dd/yyyy} | G22: Total Insole | H22: =SUMIF(C51:C201,'Data Validation'!A4,S51:S201)+SUMIF(C206:C220,'Data Validation'!A4,S206:S211) -> 0 | I22: BOM + Additional BOM | K22: # Cut & Prep LEATHER | L22: =Y49 -> 0 | M22: # Cut & Prep LEATHER TCT (mins) | N22: =VLOOKUP(CONCATENATE("# Cut & Prep LEATHER",L22),'TCT Lookup'!A:E,5,FALSE) -> 0 | O22: ASSEMBLY | R22: TCT (mins) | V22: =SUMIF(C206:C220,'Data Validation'!A4,S206:S211) -> 0
D23: Quote Good Until | E23: {*du|var:scQuoteGoodUntil|ft:com.lcs.wc.sourcing.LCSCostSheet|param:DATE_FORMAT~mm/dd/yyyy} | G23: Total Bottom | H23: =SUMIF(C51:C201,'Data Validation'!A5,S51:S201)+SUMIF(C206:C220,'Data Validation'!A5,S206:S211) -> 0 | I23: BOM + Additional BOM | K23: Pair Matching | L23: =Z49 -> 0 | M23: # Pair Matching TCT (mins) | N23: =IFERROR(VLOOKUP(CONCATENATE("# Cut & Prep LEATHER PAIR MATCHING",L23),'TCT Lookup'!A:E,5,FALSE),0) -> 0 | O23: Heel counter 1 | Q23: Heel counter TCT (mins) | R23: =IFERROR(VLOOKUP(CONCATENATE("Heel counter",P23),'TCT Lookup'!A:E,5,FALSE),0) -> 0 | V23: =SUMIF(C206:C220,'Data Validation'!A5,S206:S211) -> 0
D24: Quote Units | E24: {*du|var:scQuoteUnits|ft:com.lcs.wc.sourcing.LCSCostSheet} | G24: Total Sundries | H24: =SUMIF(C51:C201,'Data Validation'!A6,S51:S201)+SUMIF(C206:C220,'Data Validation'!A6,S206:S211) -> 0 | I24: BOM + Additional BOM | K24: Shoes Height | M24: # Pair Matching TCT (mins) | N24: =IFERROR(VLOOKUP(CONCATENATE("Shoes Height",L24),'TCT Lookup'!A:E,5,FALSE),0) -> 0 | O24: Heel counter 2 | Q24: Heel counter TCT (mins) | R24: =IFERROR(VLOOKUP(CONCATENATE("Heel counter",P24),'TCT Lookup'!A:E,5,FALSE),0) -> 0 | V24: =SUMIF(C206:C220,'Data Validation'!A6,S206:S211) -> 0
D25: First Sale Markup | E25: {*du|var:scFirstSaleMarkup|ft:com.lcs.wc.sourcing.LCSCostSheet} | G25: Total Packaging | H25: =SUMIF(C51:C201,'Data Validation'!A7,S51:S201)+SUMIF(C206:C220,'Data Validation'!A7,S206:S211) -> 0 | I25: BOM + Additional BOM | K25: # of stitched upper pcs | L25: =AA49 -> 0 | M25: # of stitched upper pcs TCT (mins) | N25: =VLOOKUP(CONCATENATE("# Stitched upper pieces",L25),'TCT Lookup'!A:E,5,FALSE) -> 0 | O25: Construction type | Q25: Construction type TCT (mins) | R25: =IFERROR(VLOOKUP(CONCATENATE(O25,P25),'TCT Lookup'!A:E,5,FALSE),0) -> 0 | V25: =SUMIF(C206:C220,'Data Validation'!A7,S206:S211) -> 0
D26: Vendor Cost Comments | E26: {*du|var:scVendorCostComments|ft:com.lcs.wc.sourcing.LCSCostSheet} | G26: BOM Override | H26: 0 | K26: # Stitch and Turn | L26: =AB49 -> 0 | M26: # Stitch and Turn TCT (mins) | N26: =VLOOKUP(CONCATENATE("# Stitch & turns",L26),'TCT Lookup'!A:E,5,FALSE) -> 0 | O26: Outsole stitching | Q26: Outsole stitching TCT (mins) | R26: =IFERROR(VLOOKUP(CONCATENATE(O26,P26),'TCT Lookup'!A:E,5,FALSE),0) -> 0
G27: LOH Total | H27: =SUM(H28:H31) -> 43.945291 | K27: # Folded Edge | L27: =AC49 -> 0 | M27: # Folded Edge TCT (mins) | N27: =IFERROR(VLOOKUP(CONCATENATE("# Folded edges",L27),'TCT Lookup'!A:E,5,FALSE),0) -> 0 | O27: Upper & Bottom Line-Up | R27: =IFERROR(VLOOKUP(CONCATENATE(O27,P27),'TCT Lookup'!A:E,5,FALSE),0) -> 0
D28: LOH Rate | E28: =SUM(E29:E30) -> 8 | G28: Upper Preparation | H28: =SUM((N20:N27),(N30:N34),(N36:N38),(N40:N43))*E28 -> 42.23176 | I28: Sum of Upper Preparation * LOH Rate | K28: Special upper construction | M28: Special upper construction TCT (mins) | N28: =IFERROR(VLOOKUP(CONCATENATE("Special upper construction",L28),'TCT Lookup'!A:E,5,FALSE),0) -> 0 | O28: Sockliner | Q28: Sockliner TCT (mins) | R28: =IFERROR(VLOOKUP(CONCATENATE(O28,P28),'TCT Lookup'!A:E,5,FALSE),0) -> 0
D29: Labor Rate | E29: 5 | G29: Stockfitting | H29: =SUM(R20:R21)*E28 -> 1.7135312 | I29: Sum of Stockfitting * LOH Rate | K29: Lacing system | O29: # attached components during assembly | P29: =AG49 -> 0 | Q29: # Attached components during assembly TCT (mins) | R29: =IFERROR(VLOOKUP(CONCATENATE(O29,P29),'TCT Lookup'!A:E,5,FALSE),0) -> 0
D30: OH Rate | E30: 3 | G30: Assembly | H30: =IFERROR(SUM(R23:R31)*E28,0) -> 0 | I30: Sum of Assembly * LOH Rate | K30: Punch holes | L30: 1 | M30: Punch holes TCT (mins) | N30: =IFERROR(VLOOKUP(CONCATENATE("# Punch holes",L30),'TCT Lookup'!A:E,5,FALSE),0) -> 0.051502146 | O30: Lacing | Q30: Lacing TCT (mins) | R30: =IFERROR(VLOOKUP(CONCATENATE(O30,P30),'TCT Lookup'!A:E,5,FALSE),0) -> 0
G31: Other process | H31: =SUM(R33:R39)*E28 -> 0 | I31: Sum of Other process * LOH Rate | K31: Metal eyelets | L31: 4 | M31: Metal eyelets TCT (mins) | N31: =IFERROR(VLOOKUP(CONCATENATE("# Metal eyelets",L31),'TCT Lookup'!A:E,5,FALSE),0) -> 0.41201717 | O31: Packaging | Q31: Packaging TCT (mins) | R31: =IFERROR(VLOOKUP(CONCATENATE(O31,P31),'TCT Lookup'!A:E,5,FALSE),0) -> 0
D32: Profit % | E32: 5 | G32: Profit | H32: =(H19+H27)*(E32/100) -> 2.1972645 | I32: (LOH + Materials) * Tooling | K32: Inserted lace loops | L32: 1 | M32: Inserted lace loops TCT (mins) | N32: =IFERROR(VLOOKUP(CONCATENATE("# Lace loops (inserted)",L32),'TCT Lookup'!A:E,5,FALSE),0) -> 0.90128755 | O32: OTHER PROCESSES | R32: TCT (mins)
D33: Overhead Premium % | E33: 5 | G33: Tooling | H33: 0 | K33: Stitched on lace loops | L33: 1 | M33: Stitched on lace loops TCT (mins) | N33: =IFERROR(VLOOKUP(CONCATENATE("# Lace loops (stitched on)",L33),'TCT Lookup'!A:E,5,FALSE),0) -> 0.33476395 | P33: =IF(COUNTA(P34,P35,P36,P37,P38,P39)=0, "", IF(COUNTA(P34,P35,P36,P37,P38,P39)=1, IF(P34<>"", P34, IF(P35<>"", P35, IF(P36<>"", P36, IF(P37<>"", P37, IF(P38<>"", P38, P39))))), P34&IF(P35<>"", "; "&P35, "")&IF(P36<>"", "; "&P36, "")&IF(P37<>"", "; "&P37, "")&IF(P38<>"", "; "&P38, "")&IF(P39<>"", "; "&P39, ""))) | Q33: Other Processes TCT (mins) | R33: =SUM(R34:R39) -> 0
G34: Overhead Premium $ | H34: =IF(ISERROR((H19+H27+H32+H33)/(1/(E33/100)-1)),0,(H19+H27+H32+H33)/(1/(E33/100)-1)) -> 2.4285555 | K34: Ghillies | L34: 1 | M34: Ghillies TCT (mins) | N34: =IFERROR(VLOOKUP(CONCATENATE("# Ghillies",L34),'TCT Lookup'!A:E,5,FALSE),0) -> 0.36051502 | R34: 0
G35: Vendor Cost | H35: =H19+H27+H32+H33+H34 -> 48.571111 | K35: Types and # of special stitch
K36: Lock stitch/overlock stitch/Flat Stitch | L36: 1 | M36: Lock stitch/Overlock Stitch/Flat Stitch TCT (mins) | N36: =IFERROR(VLOOKUP(CONCATENATE("# Lock stitch/overlock stitch/Flat stitch",L36),'TCT Lookup'!A:E,5,FALSE),0) -> 0.38626609
K37: Box stitch | L37: 1 | M37: Box Stitch TCT (mins) | N37: =IFERROR(VLOOKUP(CONCATENATE("# Box stitch",L37),'TCT Lookup'!A:E,5,FALSE),0) -> 0.36051502 | R37: 0
K38: Triple stitch | L38: 1 | M38: Triple stitch TCT (mins) | N38: =IFERROR(VLOOKUP(CONCATENATE("# Triple stitch",L38),'TCT Lookup'!A:E,5,FALSE),0) -> 0.54077253 | R38: 0
K39: Types and # of binding | R39: 0
K40: English binding | L40: =AD49 -> 0 | M40: English binding TCT (mins) | N40: =IFERROR(VLOOKUP(CONCATENATE("# English (incl. piping)",L40),'TCT Lookup'!A:E,5,FALSE),0) -> 0
K41: French binding | L41: =AE49 -> 0 | M41: French binding TCT (mins) | N41: =IFERROR(VLOOKUP(CONCATENATE("# French binding",L41),'TCT Lookup'!A:E,5,FALSE),0) -> 0
K42: No sew binding | L42: 3 | M42: No sew binding TCT (mins) | N42: =IFERROR(VLOOKUP(CONCATENATE("# No sew binding",L42),'TCT Lookup'!A:E,5,FALSE),0) -> 1.9313305 | P42: Total Cycle Time | R42: =SUM(R33:R39,R23:R31,R20:R21,N20:N28,N30:N34,N40:N43,N36:N38) -> 5.4931614
K43: Pocket construction | M43: Pocket construction TCT (mins) | N43: =IFERROR(VLOOKUP(CONCATENATE("Pocket construction", L43),'TCT Lookup'!A:E,5,FALSE),0) -> 0
C48: BILL OF MATERIALS | W48: UPPER PREPARATION | AF48: Stockfitting | AG48: Assembly
W49: =SUM(W51:W213) -> 0 | X49: =SUM(X51:X213) -> 0 | Y49: =SUM(Y51:Y213) -> 0 | Z49: =SUM(Z51:Z213) -> 0 | AA49: =SUM(AA51:AA213) -> 0 | AB49: =SUM(AB51:AB213) -> 0 | AC49: =SUM(AC51:AC213) -> 0 | AD49: =SUM(AD51:AD213) -> 0 | ... AG49: =SUM(AG51:AG213) -> 0
C50: Section | D50: Component or Location | E50: Material ID | F50: Material Name | G50: Supplier | H50: Comment | I50: BOM UOM | J50: BOM Price | K50: Price OVR | L50: CIF | N50: Quantity | O50: Wastage % | P50: Calculation Size % | R50: Gross Quantity | S50: Total Mat Cost | T50: BOM Link ID | W50: # Textile/ synthetic pcs. | X50: # Textile/ synthetic pcs for single layer cutting | Y50: # Cut & Prep LEATHER | Z50: Pair Matching | AA50: # of stitched upper pcs | AB50: # Stitch and Turn | AC50: # Folded Edge | AD50: English binding | AE50: French binding | AF50: No. of total bottom pieces | AG50: No. of attached components during assembly
...

Sheet Data Validation
A1: Section | B1: Special upper construction | C1: Pocket construction | D1: Heel counter | E1: Construction type | F1: Outsole stitching | G1: Sockliner | H1: Lacing | I1: Packaging | J1: Cost Sheet Milestone | K1: Incoterms | L1: Vendor Cost Sheet Status | M1: Destination | N1: Sample Size | O1: Shoes Height | P1: Upper & Bottom Line-Up | Q1: Incoterms Location
A2: Upper | B2: None | C2: Yes | D2: No heel counter | E2: Board | F2: None | G2: Cemented sockliner | H2: No lacing | I2: Normal packaging | J2: {*d|var:scMilestoneStatus|ft:com.lcs.wc.sourcing.LCSCostSheet|dir:column|param:ENUM_EXPORT~Y} | K2: {*d|var:scIncoterms|ft:com.lcs.wc.sourcing.LCSCostSheet|dir:column|param:ENUM_EXPORT~Y} | L2: Draft | N2: W7 | O2: KIDS Low/mid cut | P2: Yes | Q2: {*d|var:scIncotermlocation|ft:com.lcs.wc.sourcing.LCSCostSheet|dir:column|param:OBJ_REF_LIST_EXPORT~Y}
A3: Sockliner | B3: Lining/Half bootie construction | C3: No | D3: TR heel counter | E3: Board Vulcanized | F3: 1 x half stitching | G3: Drop-in sockliner | H3: Normal threading | I3: Special packaging | L3: Requested | N3: M9 | O3: KIDS High cut | P3: No
A4: Insole | B4: Tongue wing construction | D4: Thermo sheet heel counter | E4: Cold cement foxing | F4: 2 x half stitching | G4: No sockliner | H4: Additional spare laces | L4: Vendor Submitted | N4: M11 | O4: KIDS Boot cut
A5: Bottom | B5: Gusset/Bootie construction | D5: External heel counter (glued) | E5: Full Feather/Cage | F5: Full stitching | H5: Special lacing for cosmetic effects | L5: In Negotiation | N5: U9 | O5: ADULT Low/mid cut
A6: Sundries | E6: Half Feather | L6: Negotiated | N6: Special Sample | O6: ADULT High cut
A7: Packaging | E7: Moccasin | L7: Rejected | O7: ADULT Boot cut
E8: Strobel
E9: Strobel & half board
E10: Strobel & board
E11: Strobel & Toe Lasting
E12: Strobel forefoot & heel stitching
E13: Strobel to midsole
E14: Strobel Vulcanized
E15: Top plate/Bottom plate construction
E16: Triple lasting
E17: Upper stitching to outsole

Sheet TCT Lookup
A1: Id | B1: Complexity Group | C1: Complexity Criteria | D1: Criteria Details/ Quantity | E1: Cycle Time in Mins
A2: # Attached components during assembly0 | B2: Assembly | C2: # Attached components during assembly | D2: 0 | E2: 0
A3: # Attached components during assembly1 | B3: Assembly | C3: # Attached components during assembly | D3: 1 | E3: 2.5236052
A4: # Attached components during assembly2 | B4: Assembly | C4: # Attached components during assembly | D4: 2 | E4: 5.0729614
A5: # Attached components during assembly3 | B5: Assembly | C5: # Attached components during assembly | D5: 3 | E5: 7.5965665
A6: # Attached components during assembly4 | B6: Assembly | C6: # Attached components during assembly | D6: 4 | E6: 10.120172
A7: # Attached components during assembly5 | B7: Assembly | C7: # Attached components during assembly | D7: 5 | E7: 12.669528
A8: # Attached components during assembly6 | B8: Assembly | C8: # Attached components during assembly | D8: 6 | E8: 15.201717
A9: # Attached components during assembly7 | B9: Assembly | C9: # Attached components during assembly | D9: 7 | E9: 17.716738
A10: # Attached components during assembly8 | B10: Assembly | C10: # Attached components during assembly | D10: 8 | E10: 20.274678
A11: # Attached components during assembly9 | B11: Assembly | C11: # Attached components during assembly | D11: 9 | E11: 22.7897
A12: # Attached components during assembly10 | B12: Assembly | C12: # Attached components during assembly | D12: 10 | E12: 25.313305
A13: # English (incl. piping)0 | B13: Binding | C13: # English (incl. piping) | D13: 0 | E13: 0
A14: # English (incl. piping)1 | B14: Binding | C14: # English (incl. piping) | D14: 1 | E14: 0.38626609
A15: # English (incl. piping)2 | B15: Binding | C15: # English (incl. piping) | D15: 2 | E15: 0.77253219
A16: # English (incl. piping)3 | B16: Binding | C16: # English (incl. piping) | D16: 3 | E16: 1.1587983
A17: # English (incl. piping)4 | B17: Binding | C17: # English (incl. piping) | D17: 4 | E17: 1.5450644
A18: # English (incl. piping)5 | B18: Binding | C18: # English (incl. piping) | D18: 5 | E18: 1.9313305
A19: # English (incl. piping)6 | B19: Binding | C19: # English (incl. piping) | D19: 6 | E19: 2.3175966
A20: # English (incl. piping)7 | B20: Binding | C20: # English (incl. piping) | D20: 7 | E20: 2.7038627
A21: # English (incl. piping)8 | B21: Binding | C21: # English (incl. piping) | D21: 8 | E21: 3.0901288
A22: # English (incl. piping)9 | B22: Binding | C22: # English (incl. piping) | D22: 9 | E22: 3.4763948
A23: # English (incl. piping)10 | B23: Binding | C23: # English (incl. piping) | D23: 10 | E23: 3.8626609
A24: # English (incl. piping)11 | B24: Binding | C24: # English (incl. piping) | D24: 11 | E24: 4.248927
A25: # English (incl. piping)12 | B25: Binding | C25: # English (incl. piping) | D25: 12 | E25: 4.6351931
... A336: # Recess points and # Emboss/deboss windows99 | B336: Bottom | C336: # Recess points and # Emboss/deboss windows | D336: 99 | E336: 1.4230569
A337: Construction typeBoard | B337: Construction type | C337: Construction type | D337: Board | E337: 9.2703863
A338: Construction typeBoard Vulcanized | B338: Construction type | C338: Construction type | D338: Board Vulcanized | E338: 14.420601
A339: Construction typeCold cement foxing | B339: Construction type | C339: Construction type | D339: Cold cement foxing | E339: 11.072961
A340: Construction typeFull Feather/Cage | B340: Construction type | C340: Construction type | D340: Full Feather/Cage | E340: 16.738197
A341: Construction typeHalf Feather | B341: Construction type | C341: Construction type | D341: Half Feather | E341: 14.16309
A342: Construction typeMoccasin | B342: Construction type | C342: Construction type | D342: Moccasin | E342: 9.527897
A343: Construction typeStrobel | B343: Construction type | C343: Construction type | D343: Strobel | E343: 9.0128755
A344: Construction typeStrobel & half board | B344: Construction type | C344: Construction type | D344: Strobel & half board | E344: 11.330472
A345: Construction typeStrobel & board | B345: Construction type | C345: Construction type | D345: Strobel & board | E345: 11.845494
A346: Construction typeStrobel & Toe Lasting | B346: Construction type | C346: Construction type | D346: Strobel & Toe Lasting | E346: 10.55794
A347: Construction typeStrobel forefoot & heel stitching | B347: Construction type | C347: Construction type | D347: Strobel forefoot & heel stitching | E347: 9.7854077
A348: Construction typeStrobel to midsole | B348: Construction type | C348: Construction type | D348: Strobel to midsole | E348: 9.527897
... A352: Construction typeUpper stitching to outsole | B352: Construction type | C352: Construction type | D352: Upper stitching to outsole | E352: 5.9227468
A353: # Cut & Prep LEATHER0 | B353: Cut & Prep | C353: # Cut & Prep LEATHER | D353: 0 | E353: 0
...
