Workbook
Name AttributeType: #REF!
Name AttributeType2: #REF!
Name BooleanValues: #REF!
Name brand: [1]lookup!$A$2:$A$25
Name CBD_SHOE_HEIGHT: [2]drop_down!$B$2:$B$5
Name ColorControlMode: #REF!
Name ComponentComposition: #REF!
Name CompositesConstruction: #REF!
Name coo: [1]lookup!$D$2:$D$25
Name CorrugatedMaterial: #REF!
Name CurrencyCode: #REF!
Name DisplayMode: #REF!
Name ElasticStructure: #REF!
Name EndType: #REF!
Name FoldType: #REF!
Name group: [1]lookup!$B$2:$B$25
Name HookEyeBarApp: #REF!
Name HookLoopApp: #REF!
Name HookLoopForm: #REF!
Name InternalExternal: #REF!
Name kl: #REF!
Name KnitType: #REF!
Name LabelApp: #REF!
Name LabelLanguage: #REF!
Name LeatherSatra: #REF!
Name LeatherSubtype: #REF!
Name LeatherThickness: #REF!
Name LeatherType: #REF!
Name Level: #REF!
Name lo: [1]lookup!$C$2:$C$25
Name MaterialComposition: #REF!
Name MaterialDevelopmentStatus: #REF!
Name MaterialPricingMode: #REF!
Name MaterialSupplierStatus: #REF!
Name MetalCategory: #REF!
Name MetalForm: #REF!
Name MetalShape: #REF!
Name PackagingCoatingFinishing: #REF!
Name PackagingMaterialQuality: #REF!
Name PackagingType: #REF!
Name PaymentTerms: #REF!
Name ProductSampleType: #REF!
Name RawMaterial: #REF!
Name SampleProductType: #REF!
Name SampleStatus: #REF!
Name SampleSubType: #REF!
Name SampleType: #REF!
Name Scope: #REF!
Name Shipping: #REF!
Name SizeWeight: #REF!
Name SnapCover: #REF!
Name source: [3]TechPack!$M$2:$M$11
Name SpecialClaims: #REF!
Name StampFinishPattern: #REF!
Name Standard: #REF!
Name Strength: #REF!
Name Structure: #REF!
Name SubA: [4]Materials!$M$30
Name SubB: [4]Materials!$M$36
Name SubC: [4]Materials!$M$40

Sheet Detailed Apparel Cost Sheet
M1: 6
C2: Apparel Cost Break Down
C5: PRODUCT SUMMARY
C6: SEASON: | D6: {*du|var:plmSeasonName|locked} | F6: PLM PRODUCT #: | G6: {*du|var:plmProductNumber|locked} | I6: COLORWAY NAME: | J6: {*d|var:costSheetSelectedColorwayNames|locked} | N6: USER EMAIL: | O6: {*ud|var:exportedUserMail}
C7: COST SHEET MILESTONE: | D7: Please Select | F7: PRODUCT DESCRIPTION: | G7: {*d|var:scProductDescription|locked|ft:com.lcs.wc.product.LCSProduct} | I7: COLORWAY #: | J7: {*du|var:costSheetSelectedColorwayIds|locked} | N7: REP COLORWAY FORECAST: | O7: {*d|var:scInitialEstimatedUnits|locked|ft:com.lcs.wc.season.LCSSKUSeasonLink}
C8: COST SHEET NAME: | D8: {*du|var:plmCostSheetName} | I8: REPRESENTATIVE COLORWAY: | J8: {*d|var:representativeColorwayName|locked} | N8: TARGET VENDOR QUOTE: | O8: {*d|var:scTargetVendorQuote|locked|ft:com.lcs.wc.sourcing.LCSCostSheet}
C9: COST SHEET NUMBER: | D9: {*du|var:plmCostSheetNumber|locked}
C10: SOURCING CONFIG: | D10: {*d|var:sourcingConfigName|locked}
C11: COUNTRY OF ORIGIN | D11: {*d|var:countryOfOrigin|locked}
C12: SPECIFICATION: | D12: {*d|var:specificationName|locked}
C15: COST SUMMARY
D17: COST SHEET DETAILS | G17: MATERIALS BREAKDOWN | J17: COST INPUTS | N17: VENDOR COST
T18: Additional Attributes
D19: Vendor Cost Sheet Status | G19: Total Materials | H19: =IF(H27>0,H27,(SUM(H20:H26)+H28)) -> {*du|var:scBOMOverride|ft:com.lcs.wc.sourcing.LCSCostSheet} | J19: Direct Labor Cost | K19: {*du|var:scDirectLaborCost|ft:com.lcs.wc.sourcing.LCSCostSheet} | N19: Base Vendor Cost | O19: =H19+K19+K22+K26+K27 -> #VALUE! | T19: =SUMIF(C205:C220,'Data Validation'!A2,P205:P220) -> 0
D20: Incoterms | G20: Main Materials | H20: =SUMIF(C50:C200,'Data Validation'!A2,P50:P200)+SUMIF(C205:C220,'Data Validation'!A2,P205:P220) -> 0 | I20: BOM + Additional BOM | J20: OH % | K20: {*du|var:scOHPercent|ft:com.lcs.wc.sourcing.LCSCostSheet} | N20: Vendor Product Cost | O20: =IF(K30<>0, K30, O19+K28) -> {*du|var:scVendorCost|ft:com.lcs.wc.sourcing.LCSCostSheet} | T20: =SUMIF(C205:C220,'Data Validation'!A3,P205:P220) -> 0
D21: Incoterms Location | G21: Trims | H21: =SUMIF(C50:C200,'Data Validation'!A3,P50:P200)+SUMIF(C205:C220,'Data Validation'!A3,P205:P220) -> 0 | I21: BOM + Additional BOM | J21: Overhead Override | K21: {*du|var:scOverheadOverride|ft:com.lcs.wc.sourcing.LCSCostSheet} | N21: Vendor Total Cost | O21: =O20+K31+K33+K34 -> #VALUE! | T21: =SUMIF(C205:C220,'Data Validation'!A4,P205:P220) -> 0
D22: Quote Good Until | E22: {*du|var:scQuoteGoodUntil|ft:com.lcs.wc.sourcing.LCSCostSheet|param:DATE_FORMAT~mm/dd/yyyy} | G22: Lining | H22: =SUMIF(C50:C200,'Data Validation'!A4,P50:P200)+SUMIF(C205:C220,'Data Validation'!A4,P205:P220) -> 0 | I22: BOM + Additional BOM | J22: Overhead Cost | K22: =IF(K21>0, K21, K19*K20/100) -> {*du|var:scOverheadOverride|ft:com.lcs.wc.sourcing.LCSCostSheet} | T22: =SUMIF(C205:C220,'Data Validation'!A5,P205:P220) -> 0
D23: Quote Units | E23: {*du|var:scQuoteUnits|ft:com.lcs.wc.sourcing.LCSCostSheet} | G23: Artwork | H23: =SUMIF(C50:C200,'Data Validation'!A5,P50:P200)+SUMIF(C205:C220,'Data Validation'!A5,P205:P220) -> 0 | I23: BOM + Additional BOM | J23: Labor & Overhead Cost | K23: =K19+K22 -> #VALUE! | T23: =SUMIF(C205:C220,'Data Validation'!A6,P205:P220) -> 0
D24: Vendor Cost Comments | E24: {*du|var:scVendorCostComments|ft:com.lcs.wc.sourcing.LCSCostSheet} | G24: Process | H24: =SUMIF(C50:C200,'Data Validation'!A6,P50:P200)+SUMIF(C205:C220,'Data Validation'!A6,P205:P220) -> 0 | I24: BOM + Additional BOM | J24: Profit % | K24: {*du|var:scProfitPercent|ft:com.lcs.wc.sourcing.LCSCostSheet} | T24: =SUMIF(C205:C220,'Data Validation'!A7,P205:P211) -> 0
D25: Style MOQ | E25: {*du|var:scStyleMOQ|ft:com.lcs.wc.sourcing.LCSCostSheet} | G25: Labels | H25: =SUMIF(C50:C200,'Data Validation'!A7,P50:P200)+SUMIF(C205:C220,'Data Validation'!A7,P205:P220) -> 0 | I25: BOM + Additional BOM | J25: Profit Override | K25: {*du|var:scProfitOverride|ft:com.lcs.wc.sourcing.LCSCostSheet} | T25: =SUMIF(C205:C220,'Data Validation'!A8,P205:P211) -> 0
D26: MOQ Comments | E26: {*du|var:scMOQComments|ft:com.lcs.wc.sourcing.LCSCostSheet} | G26: Packaging | H26: =SUMIF(C50:C200,'Data Validation'!A8,P50:P200)+SUMIF(C205:C220,'Data Validation'!A8,P205:P220) -> 0 | J26: Profit $ | K26: =IF(K25>0,K25,(H19+K23)*K24/100) -> {*du|var:scProfitOverride|ft:com.lcs.wc.sourcing.LCSCostSheet}
D27: Color MOQ | E27: {*du|var:scColorMOQ|ft:com.lcs.wc.sourcing.LCSCostSheet} | G27: BOM Override | H27: {*du|var:scBOMOverride|ft:com.lcs.wc.sourcing.LCSCostSheet} | J27: Product Testing Cost | K27: {*du|var:scProductTestingCost|ft:com.lcs.wc.sourcing.LCSCostSheet}
D28: Lead Time (PO to Ship) | E28: {*du|var:scLeadTimePOtoShip|ft:com.lcs.wc.sourcing.LCSCostSheet} | G28: Tooling Amortization | H28: {*du|var:scToolingAmortization|ft:com.lcs.wc.sourcing.LCSCostSheet} | I28: Sum of Upper Preparation * LOH Rate | J28: Upcharge / Discount | K28: {*du|var:scUpchargeDiscount|ft:com.lcs.wc.sourcing.LCSCostSheet}
J29: Upcharge / Discount Comments | K29: {*du|var:scUpchargeDiscountComments|ft:com.lcs.wc.sourcing.LCSCostSheet}
I30: Sum of Assembly * LOH Rate | J30: Vendor Product Cost Override | K30: {*du|var:scVendorCost|ft:com.lcs.wc.sourcing.LCSCostSheet}
D31: Hanger Cost | E31: {*du|var:scHangerCost|ft:com.lcs.wc.sourcing.LCSCostSheet} | I31: Sum of Other process * LOH Rate | J31: Other Vendor Costs | K31: {*du|var:scUnitsOtherCosts|ft:com.lcs.wc.sourcing.LCSCostSheet}
D32: Vendor Paid Testing Cost | E32: {*du|var:scVendorPaidTestingCost|ft:com.lcs.wc.sourcing.LCSCostSheet} | I32: (LOH + Materials) * Tooling | J32: Agent Commission % - US | K32: {*du|var:scAgentCommissionPercentUS|ft:com.lcs.wc.sourcing.LCSCostSheet}
D33: First Sale Markup | E33: {*du|var:scFirstSaleMarkup|ft:com.lcs.wc.sourcing.LCSCostSheet} | J33: Agent Commission $ - US | K33: =(K32/100)*(O20+K31) -> #VALUE!
J34: Marketing Royalty $ - US | K34: {*du|var:scMarketingroyalty|ft:com.lcs.wc.sourcing.LCSCostSheet}
C47: BILL OF MATERIALS
C49: Section | D49: Component or Location | E49: Material ID | F49: Material Name | G49: Supplier | H49: Comment | I49: BOM UOM | J49: BOM Price | K49: Price OVR | L49: CIF | M49: Quantity | N49: Wastage % | O49: Gross Quanitty | P49: Total Mat Cost | Q49: BOM Link ID
D50: {*d|var:scComponent|dir:column|grouped|locked|ft:com.lcs.wc.flexbom.FlexBOMLink|param:HRR~true|param:RR~150} | E50: {*d|var:scMaterialNo|dir:column|grouped|locked|ft:com.lcs.wc.material.LCSMaterial|param:HRR~true|param:RR~150} | F50: {*d|var:materialDescription|dir:column|grouped|locked|ft:com.lcs.wc.flexbom.FlexBOMLink|param:HRR~true|param:RR~150} | G50: {*d|var:name|dir:column|grouped|locked|ft:com.lcs.wc.supplier.LCSSupplier|param:HRR~true|param:RR~150} | H50: {*d|var:scComments|dir:column|grouped|locked|ft:com.lcs.wc.flexbom.FlexBOMLink|param:HRR~true|param:RR~150} | I50: {*d|var:bomUOM|dir:column|grouped|locked|param:HRR~true|param:RR~150} | J50: {*d|var:materialPrice|dir:column|grouped|locked|ft:com.lcs.wc.material.LCSMaterialSupplier|param:HRR~true|param:RR~150} | K50: {*du|var:priceOverride|dir:column|grouped|ft:com.lcs.wc.flexbom.FlexBOMLink|param:HRR~true|param:RR~150} | L50: {*du|var:scCIF|dir:column|grouped|ft:com.lcs.wc.flexbom.FlexBOMLink|param:HRR~true|param:RR~150} | M50: {*du|var:quantity|dir:column|grouped|ft:com.lcs.wc.flexbom.FlexBOMLink|param:HRR~true|param:RR~150} | N50: {*du|var:lossAdjustment|dir:column|grouped|ft:com.lcs.wc.flexbom.FlexBOMLink|param:HRR~true|param:RR~150} | O50: =M50*(1+N50) -> #VALUE! | P50: =IF(OR(K50<>0, K50<>""), (K50+L50)*O50, O50*(J50+L50)) -> #VALUE! | Q50: {*du|var:bomLinkId|dir:column|grouped|locked|param:HRR~true|param:RR~150}
O51: =M51*(1+N51) -> 0 | P51: =IF(OR(K51<>0, K51<>""), (K51+L51)*O51, O51*(J51+L51)) -> 0
O52: =M52*(1+N52) -> 0 | P52: =IF(OR(K52<>0, K52<>""), (K52+L52)*O52, O52*(J52+L52)) -> 0
O53: =M53*(1+N53) -> 0 | P53: =IF(OR(K53<>0, K53<>""), (K53+L53)*O53, O53*(J53+L53)) -> 0
O54: =M54*(1+N54) -> 0 | P54: =IF(OR(K54<>0, K54<>""), (K54+L54)*O54, O54*(J54+L54)) -> 0
O55: =M55*(1+N55) -> 0 | P55: =IF(OR(K55<>0, K55<>""), (K55+L55)*O55, O55*(J55+L55)) -> 0
O56: =M56*(1+N56) -> 0 | P56: =IF(OR(K56<>0, K56<>""), (K56+L56)*O56, O56*(J56+L56)) -> 0
O57: =M57*(1+N57) -> 0 | P57: =IF(OR(K57<>0, K57<>""), (K57+L57)*O57, O57*(J57+L57)) -> 0
O58: =M58*(1+N58) -> 0 | P58: =IF(OR(K58<>0, K58<>""), (K58+L58)*O58, O58*(J58+L58)) -> 0
...

Sheet Data Validation
A1: Section | B1: Cost Sheet Milestone | C1: Vendor Cost Sheet Status | D1: Incoterms | E1: Destination | F1: Incoterm Locations
A2: Main Materials | B2: {*d|var:scMilestoneStatus|ft:com.lcs.wc.sourcing.LCSCostSheet|dir:column|param:ENUM_EXPORT~Y} | C2: Draft | D2: {*d|var:scIncoterms|ft:com.lcs.wc.sourcing.LCSCostSheet|dir:column|param:ENUM_EXPORT~Y} | F2: {*d|var:scIncotermlocation|ft:com.lcs.wc.sourcing.LCSCostSheet|dir:column|param:OBJ_REF_LIST_EXPORT~Y}
A3: Trims | C3: Requested
A4: Lining | C4: Vendor Submitted
A5: Artwork | C5: In Negotiation
A6: Process | C6: Negotiated
A7: Labels | C7: Rejected
A8: Packaging
